<robot name="onshape">
<link name="wrist_1">
<collision>
<origin xyz="-0.036586 -0.324104 0.087087" rpy="-2.53263 0.00439039 -3.13599" />
<geometry>
<mesh filename="package://servo.stl"/>
</geometry>
<material name="servo_material">
<color rgba="0.25098 0.25098 0.25098 1.0"/>
</material>
</collision>
<collision>
<origin xyz="-0.036561 -0.325276 0.0854659" rpy="0.608966 0.00439039 -3.13599" />
<geometry>
<mesh filename="package://part_1.stl"/>
</geometry>
<material name="part_1_material">
<color rgba="0.501961 0.501961 0.501961 1.0"/>
</material>
</collision>
<collision>
<origin xyz="-0.0221441 -0.273632 0.146654" rpy="-0.393492 0.00439039 -3.13599" />
<geometry>
<mesh filename="package://imported15.stl"/>
</geometry>
<material name="imported15_material">
<color rgba="0.917647 0.917647 0.917647 1.0"/>
</material>
</collision>
<collision>
<origin xyz="-0.0131671 -0.296957 0.125988" rpy="-2.53263 0.00439039 -3.13599" />
<geometry>
<mesh filename="package://bb-03.stl"/>
</geometry>
<material name="bb-03_material">
<color rgba="0.647059 0.647059 0.647059 1.0"/>
</material>
</collision>
<collision>
<origin xyz="-0.0131671 -0.296957 0.125988" rpy="-0.608966 -0.00439039 0.00560636" />
<geometry>
<mesh filename="package://imported30.stl"/>
</geometry>
<material name="imported30_material">
<color rgba="0.231373 0.380392 0.705882 1.0"/>
</material>
</collision>
<visual>
<origin xyz="0 0 0" rpy="0 -0 0" />
<geometry>
<mesh filename="package://wrist_1.stl"/>
</geometry>
<material name="wrist_1_material">
<color rgba="0.436028 0.436736 0.438282 1.0"/>
</material>
</visual>
<inertial>
<origin xyz="-0.0361093 -0.313655 0.102111" rpy="0 0 0"/>
<mass value="0.0622741" />
<inertia ixx="2.36538e-05" ixy="-3.8553e-07"  ixz="-7.51646e-07" iyy="4.22717e-05" iyz="-8.54433e-06" izz="3.59672e-05" />
</inertial>
</link>

<link name="elbow_1">
<collision>
<origin xyz="-0.0244212 -0.0220573 0.0354369" rpy="-1.5708 -0.568339 3.14159" />
<geometry>
<mesh filename="package://imported11.stl"/>
</geometry>
<material name="imported11_material">
<color rgba="0.231373 0.380392 0.705882 1.0"/>
</material>
</collision>
<collision>
<origin xyz="-0.125879 -0.0512165 0.0975185" rpy="-1.5708 -0.568339 3.14159" />
<geometry>
<mesh filename="package://asb201b.stl"/>
</geometry>
<material name="asb201b_material">
<color rgba="0.498039 0.498039 0.498039 1.0"/>
</material>
</collision>
<collision>
<origin xyz="-5.55112e-17 0.0015 5.55112e-17" rpy="-3.95929e-19 7.43601e-17 7.76416e-19" />
<geometry>
<mesh filename="package://imported8.stl"/>
</geometry>
<material name="imported8_material">
<color rgba="0.231373 0.380392 0.705882 1.0"/>
</material>
</collision>
<collision>
<origin xyz="-0.130334 -0.0220573 0.084903" rpy="2.13914 3.52335e-15 1.5708" />
<geometry>
<mesh filename="package://at-03.stl"/>
</geometry>
<material name="at-03_material">
<color rgba="0.768627 0.886275 0.952941 1.0"/>
</material>
</collision>
<collision>
<origin xyz="-0.13301 -0.0220573 0.0866118" rpy="-2.57325 3.57736e-15 1.5708" />
<geometry>
<mesh filename="package://hub-08.stl"/>
</geometry>
<material name="hub-08_material">
<color rgba="0.917647 0.917647 0.917647 1.0"/>
</material>
</collision>
<collision>
<origin xyz="-0.0303533 -0.0379467 0.00732965" rpy="-2.57325 3.4209e-15 1.5708" />
<geometry>
<mesh filename="package://imported15.stl"/>
</geometry>
<material name="imported15_material">
<color rgba="0.611765 0.811765 0.921569 1.0"/>
</material>
</collision>
<collision>
<origin xyz="-0.123429 -0.0220573 0.0986658" rpy="-1.5708 0.568339 -7.43777e-15" />
<geometry>
<mesh filename="package://imported11.stl"/>
</geometry>
<material name="imported11_material">
<color rgba="0.231373 0.380392 0.705882 1.0"/>
</material>
</collision>
<collision>
<origin xyz="0.00113051 -0.0458571 -0.00053094" rpy="1.00246 -3.22359e-15 -1.5708" />
<geometry>
<mesh filename="package://imported30.stl"/>
</geometry>
<material name="imported30_material">
<color rgba="0.231373 0.380392 0.705882 1.0"/>
</material>
</collision>
<collision>
<origin xyz="0.000443529 -0.0274802 0.0168452" rpy="-1.5708 -0.568339 3.14159" />
<geometry>
<mesh filename="package://asb-04.stl"/>
</geometry>
<material name="asb-04_material">
<color rgba="0.647059 0.647059 0.647059 1.0"/>
</material>
</collision>
<collision>
<origin xyz="-0.168036 -0.0235167 0.101822" rpy="-1.5708 -1.00246 8.92593e-15" />
<geometry>
<mesh filename="package://imported10.stl"/>
</geometry>
<material name="imported10_material">
<color rgba="0.972549 0.529412 0.00392157 1.0"/>
</material>
</collision>
<collision>
<origin xyz="-0.031327 -0.0220573 0.0216741" rpy="0.568339 3.54935e-15 1.5708" />
<geometry>
<mesh filename="package://hub-08.stl"/>
</geometry>
<material name="hub-08_material">
<color rgba="0.917647 0.917647 0.917647 1.0"/>
</material>
</collision>
<visual>
<origin xyz="0 0 0" rpy="0 -0 0" />
<geometry>
<mesh filename="package://elbow_1.stl"/>
</geometry>
<material name="elbow_1_material">
<color rgba="0.821471 0.601159 0.31861 1.0"/>
</material>
</visual>
<inertial>
<origin xyz="-0.12068 -0.022989 0.0749584" rpy="0 0 0"/>
<mass value="1.12468" />
<inertia ixx="0.00239634" ixy="4.82258e-05"  ixz="0.00330002" iyy="0.00794344" iyz="2.52644e-05" izz="0.00587491" />
</inertial>
</link>

<link name="arm_1">
<collision>
<origin xyz="-3.38618e-15 -0.0297627 -0.0823056" rpy="4.45083e-16 -1.30243e-15 -3.14159" />
<geometry>
<mesh filename="package://imported6.stl"/>
</geometry>
<material name="imported6_material">
<color rgba="0.647059 0.647059 0.647059 1.0"/>
</material>
</collision>
<collision>
<origin xyz="0.000965268 -0.0599498 -0.000537904" rpy="-0.496906 9.71233e-16 -1.5708" />
<geometry>
<mesh filename="package://imported5.stl"/>
</geometry>
<material name="imported5_material">
<color rgba="0.980392 0.713725 0.00392157 1.0"/>
</material>
</collision>
<collision>
<origin xyz="-3.71925e-15 0.0070373 -0.146277" rpy="9.96212e-16 3.55487e-16 1.5708" />
<geometry>
<mesh filename="package://imported4.stl"/>
</geometry>
<material name="imported4_material">
<color rgba="0.231373 0.380392 0.705882 1.0"/>
</material>
</collision>
<collision>
<origin xyz="-3.64986e-15 -0.0655687 -0.146277" rpy="1.11629e-15 3.24625e-16 1.5708" />
<geometry>
<mesh filename="package://imported5.stl"/>
</geometry>
<material name="imported5_material">
<color rgba="0.980392 0.713725 0.00392157 1.0"/>
</material>
</collision>
<collision>
<origin xyz="-0.0123063 -0.0631002 -0.073025" rpy="1.5708 8.15346e-16 3.44632e-16" />
<geometry>
<mesh filename="package://asb203.stl"/>
</geometry>
<material name="asb203_material">
<color rgba="0.615686 0.811765 0.929412 1.0"/>
</material>
</collision>
<collision>
<origin xyz="1.38778e-17 0.002 -2.77556e-17" rpy="1.95874e-19 4.38707e-17 -8.6926e-19" />
<geometry>
<mesh filename="package://imported8.stl"/>
</geometry>
<material name="imported8_material">
<color rgba="0.231373 0.380392 0.705882 1.0"/>
</material>
</collision>
<visual>
<origin xyz="0 0 0" rpy="0 -0 0" />
<geometry>
<mesh filename="package://arm_1.stl"/>
</geometry>
<material name="arm_1_material">
<color rgba="0.549634 0.627756 0.687007 1.0"/>
</material>
</visual>
<inertial>
<origin xyz="4.99624e-05 -0.0221487 -0.0892021" rpy="0 0 0"/>
<mass value="0.210521" />
<inertia ixx="0.000832208" ixy="3.97597e-07"  ixz="-9.32581e-07" iyy="0.000627814" iyz="0.000105361" izz="0.000229822" />
</inertial>
</link>

<link name="shoulder_1">
<collision>
<origin xyz="0.02269 -0.00174611 -0.036506" rpy="1.5708 -1.5708 0" />
<geometry>
<mesh filename="package://imported2.stl"/>
</geometry>
<material name="imported2_material">
<color rgba="0.768627 0.886275 0.952941 1.0"/>
</material>
</collision>
<collision>
<origin xyz="-0.0118691 0.07126 -0.0250047" rpy="-3.14159 -1.5708 0" />
<geometry>
<mesh filename="package://imported1.stl"/>
</geometry>
<material name="imported1_material">
<color rgba="0.972549 0.529412 0.00392157 1.0"/>
</material>
</collision>
<collision>
<origin xyz="0.014478 -0.014986 -0.061214" rpy="4.38009e-20 9.13044e-19 1.68915e-18" />
<geometry>
<mesh filename="package://hs-805bb.stl"/>
</geometry>
<material name="hs-805bb_material">
<color rgba="0.909804 0.909804 0.909804 1.0"/>
</material>
</collision>
<visual>
<origin xyz="0 0 0" rpy="0 -0 0" />
<geometry>
<mesh filename="package://shoulder_1.stl"/>
</geometry>
<material name="shoulder_1_material">
<color rgba="0.908985 0.833727 0.73777 1.0"/>
</material>
</visual>
<inertial>
<origin xyz="-0.0168348 0.00637191 -0.0316393" rpy="0 0 0"/>
<mass value="1.2783" />
<inertia ixx="0.000710801" ixy="-3.77805e-05"  ixz="-2.19578e-05" iyy="0.000934011" iyz="-2.81715e-05" izz="0.000742463" />
</inertial>
</link>

<link name="base_1">
<collision>
<origin xyz="1.38778e-17 -0.0408164 0" rpy="-1.5708 -3.71498e-17 -8.77933e-18" />
<geometry>
<mesh filename="package://imported36.stl"/>
</geometry>
<material name="imported36_material">
<color rgba="0.917647 0.917647 0.917647 1.0"/>
</material>
</collision>
<collision>
<origin xyz="0.0565 -0.0408164 3.46945e-18" rpy="-1.5708 -3.72385e-17 -1.22544e-17" />
<geometry>
<mesh filename="package://imported36.stl"/>
</geometry>
<material name="imported36_material">
<color rgba="0.917647 0.917647 0.917647 1.0"/>
</material>
</collision>
<collision>
<origin xyz="0 -0.0423164 3.46945e-18" rpy="1.51444e-18 2.5486e-19 -1.00323e-19" />
<geometry>
<mesh filename="package://imported1.stl"/>
</geometry>
<material name="imported1_material">
<color rgba="0.917647 0.917647 0.917647 1.0"/>
</material>
</collision>
<visual>
<origin xyz="0 0 0" rpy="0 -0 0" />
<geometry>
<mesh filename="package://base_1.stl"/>
</geometry>
<material name="base_1_material">
<color rgba="0.917647 0.917647 0.917647 1.0"/>
</material>
</visual>
<inertial>
<origin xyz="0.0152028 -0.0290015 -0.000113358" rpy="0 0 0"/>
<mass value="0.859229" />
<inertia ixx="0.00086214" ixy="0.000154335"  ixz="-1.48121e-06" iyy="0.00203555" iyz="2.15863e-06" izz="0.00160879" />
</inertial>
</link>

<joint name="joint1" type="revolute">
<origin xyz="-0.0118691 0.030112 -0.0250047" rpy="3.14159 1.5708 0" />
<parent link="shoulder_1" />
<child link="base_1" />
<axis xyz="0 1 0"/>
<limit effort="1" velocity="20" lower="0" upper="6.28319"/>
<joint_properties friction="0.0"/>
</joint>

<joint name="joint2" type="revolute">
<origin xyz="-3.55271e-15 0.0004373 -0.146277" rpy="-1.5708 0.877711 5.8629e-15" />
<parent link="arm_1" />
<child link="shoulder_1" />
<axis xyz="0 0 1"/>
<limit effort="1" velocity="20" lower="-1.5708" upper="2.0944"/>
<joint_properties friction="0.0"/>
</joint>

<joint name="joint3" type="revolute">
<origin xyz="-0.153811 0.00723332 0.092738" rpy="-3.14159 -0.0714328 3.14159" />
<parent link="elbow_1" />
<child link="arm_1" />
<axis xyz="0 -1 0"/>
<limit effort="1" velocity="20" lower="-2.35619" upper="2.35619"/>
<joint_properties friction="0.0"/>
</joint>

<joint name="joint4" type="revolute">
<origin xyz="-0.0599957 -0.29722 0.125782" rpy="-3.13392 0.961817 -1.55889" />
<parent link="wrist_1" />
<child link="elbow_1" />
<axis xyz="0 -1 0"/>
<limit effort="1" velocity="20" lower="-2.53073" upper="2.53073"/>
<joint_properties friction="0.0"/>
</joint>

<link name="hand_1">
<collision>
<origin xyz="0.0103124 0.0004318 -0.0163031" rpy="-3.14159 4.46457e-15 5.83036e-17" />
<geometry>
<mesh filename="package://servo_body.stl"/>
</geometry>
<material name="servo_body_material">
<color rgba="0.25098 0.25098 0.25098 1.0"/>
</material>
</collision>
<collision>
<origin xyz="0.007495 0 -0.01259" rpy="-7.56263e-20 -5.74456e-17 -5.47395e-19" />
<geometry>
<mesh filename="package://horn.stl"/>
</geometry>
<material name="horn_material">
<color rgba="0.917647 0.917647 0.917647 1.0"/>
</material>
</collision>
<collision>
<origin xyz="0 -0.0064008 -0.004327" rpy="-6.38877e-17 1.5708 0" />
<geometry>
<mesh filename="package://gripper_wrist.stl"/>
</geometry>
<material name="gripper_wrist_material">
<color rgba="0.768627 0.886275 0.952941 1.0"/>
</material>
</collision>
<visual>
<origin xyz="0 0 0" rpy="0 -0 0" />
<geometry>
<mesh filename="package://hand_1.stl"/>
</geometry>
<material name="hand_1_material">
<color rgba="0.269207 0.273309 0.275633 1.0"/>
</material>
</visual>
<inertial>
<origin xyz="0.00975498 -0.0143998 -0.0162576" rpy="0 0 0"/>
<mass value="0.237212" />
<inertia ixx="3.42898e-05" ixy="1.80372e-06"  ixz="1.05371e-07" iyy="4.39636e-05" iyz="-1.98687e-07" izz="6.24544e-05" />
</inertial>
</link>

<link name="gripper1_1">
<collision>
<origin xyz="0.0018288 -0.006985 0.002032" rpy="-2.12221e-19 -1.84964e-19 -7.04873e-19" />
<geometry>
<mesh filename="package://gripper_finger_right.stl"/>
</geometry>
<material name="gripper_finger_right_material">
<color rgba="0.498039 0.498039 0.498039 1.0"/>
</material>
</collision>
<collision>
<origin xyz="0.000117431 -0.0449713 -0.003175" rpy="9.25804e-16 2.74838e-18 -1.5708" />
<geometry>
<mesh filename="package://gripper_finger_pad.stl"/>
</geometry>
<material name="gripper_finger_pad_material">
<color rgba="0.615686 0.811765 0.929412 1.0"/>
</material>
</collision>
<visual>
<origin xyz="0 0 0" rpy="0 -0 0" />
<geometry>
<mesh filename="package://gripper1_1.stl"/>
</geometry>
<material name="gripper1_1_material">
<color rgba="0.537311 0.602765 0.642037 1.0"/>
</material>
</visual>
<inertial>
<origin xyz="0.0111564 0.00062366 0.00218355" rpy="0 0 0"/>
<mass value="0.00484154" />
<inertia ixx="2.53263e-07" ixy="6.17859e-08"  ixz="8.65274e-08" iyy="5.53188e-07" iyz="-1.2274e-08" izz="6.75472e-07" />
</inertial>
</link>

<joint name="joint6" type="prismatic">
<origin xyz="0.0194818 -3.46945e-18 -0.0280252" rpy="-2.08852e-16 1.5708 0" />
<parent link="hand_1" />
<child link="gripper1_1" />
<axis xyz="0 0 -1"/>
<limit effort="1" velocity="20" lower="0.0005" upper="0.0012"/>
<joint_properties friction="0.0"/>
</joint>

<link name="gripper2_1">
<collision>
<origin xyz="0.0018288 -0.006985 0.002032" rpy="-4.23914e-19 -2.73728e-17 -6.56659e-19" />
<geometry>
<mesh filename="package://gripper_finger_left.stl"/>
</geometry>
<material name="gripper_finger_left_material">
<color rgba="0.917647 0.917647 0.917647 1.0"/>
</material>
</collision>
<collision>
<origin xyz="0.000117431 -0.0449713 -0.003175" rpy="1.42092e-14 2.39387e-14 -1.5708" />
<geometry>
<mesh filename="package://gripper_finger_pad.stl"/>
</geometry>
<material name="gripper_finger_pad_material">
<color rgba="0.615686 0.811765 0.929412 1.0"/>
</material>
</collision>
<visual>
<origin xyz="0 0 0" rpy="0 -0 0" />
<geometry>
<mesh filename="package://gripper2_1.stl"/>
</geometry>
<material name="gripper2_1_material">
<color rgba="0.81685 0.882303 0.921574 1.0"/>
</material>
</visual>
<inertial>
<origin xyz="0.011178 -0.000623502 0.00218369" rpy="0 0 0"/>
<mass value="0.00484161" />
<inertia ixx="2.53277e-07" ixy="-6.06441e-08"  ixz="8.60464e-08" iyy="5.48254e-07" iyz="1.22671e-08" izz="6.7054e-07" />
</inertial>
</link>

<joint name="joint7" type="prismatic">
<origin xyz="-0.0017018 3.46945e-18 -0.0280252" rpy="3.14159 1.5708 0" />
<parent link="hand_1" />
<child link="gripper2_1" />
<axis xyz="0 0 -1"/>
<limit effort="1" velocity="20" lower="0.0005" upper="0.0012"/>
<joint_properties friction="0.0"/>
</joint>

<joint name="joint5" type="revolute">
<origin xyz="-0.0290255 -0.329587 0.0791964" rpy="-0.00535255 0.608959 1.57334" />
<parent link="wrist_1" />
<child link="hand_1" />
<axis xyz="0 0 1"/>
<limit effort="1" velocity="20" lower="0" upper="6.28319"/>
<joint_properties friction="0.0"/>
</joint>


</robot>
