<robot name="onshape">
<link name="assembly_3_1">
<collision>
<origin xyz="-0.00970271 -0.0434987 0.100418" rpy="0.037808 1.24896 0.180399" />
<geometry>
<mesh filename="package://imported6.stl"/>
</geometry>
<material name="imported6_material">
<color rgba="0.647059 0.647059 0.647059 1.0"/>
</material>
</collision>
<collision>
<origin xyz="-0.0644966 -0.0884144 0.0797579" rpy="-1.24918 0.0119563 -1.42627" />
<geometry>
<mesh filename="package://imported4.stl"/>
</geometry>
<material name="imported4_material">
<color rgba="0.231373 0.380392 0.705882 1.0"/>
</material>
</collision>
<collision>
<origin xyz="-0.0749532 -0.0165706 0.0806259" rpy="-1.24918 0.0119563 -1.42627" />
<geometry>
<mesh filename="package://imported5.stl"/>
</geometry>
<material name="imported5_material">
<color rgba="0.980392 0.713725 0.00392157 1.0"/>
</material>
</collision>
<collision>
<origin xyz="0.064324 -0.00303524 0.126312" rpy="-2.68503 -0.0119563 1.71533" />
<geometry>
<mesh filename="package://imported5.stl"/>
</geometry>
<material name="imported5_material">
<color rgba="0.980392 0.713725 0.00392157 1.0"/>
</material>
</collision>
<collision>
<origin xyz="-0.00195659 -0.00857929 0.0920755" rpy="1.53299 -1.24896 -2.96119" />
<geometry>
<mesh filename="package://asb203.stl"/>
</geometry>
<material name="asb203_material">
<color rgba="0.615686 0.811765 0.929412 1.0"/>
</material>
</collision>
<collision>
<origin xyz="0.0721877 -0.0639893 0.126053" rpy="-0.037808 -1.24896 -2.96119" />
<geometry>
<mesh filename="package://imported8.stl"/>
</geometry>
<material name="imported8_material">
<color rgba="0.231373 0.380392 0.705882 1.0"/>
</material>
</collision>
<visual>
<origin xyz="0 0 0" rpy="0 -0 0" />
<geometry>
<mesh filename="package://assembly_3_1.stl"/>
</geometry>
<material name="assembly_3_1_material">
<color rgba="nan nan nan 1.0"/>
</material>
</visual>
<inertial>
<origin xyz="0 0 0" rpy="0 0 0"/>
<mass value="0" />
<inertia ixx="0" ixy="0"  ixz="0" iyy="0" iyz="0" izz="0" />
</inertial>
</link>

<link name="assembly_6_1">
<collision>
<origin xyz="0.014478 -0.014986 -0.061214" rpy="-1.07784e-18 2.49165e-18 -9.54534e-19" />
<geometry>
<mesh filename="package://hs-805bb.stl"/>
</geometry>
<material name="hs-805bb_material">
<color rgba="0.909804 0.909804 0.909804 1.0"/>
</material>
</collision>
<collision>
<origin xyz="0.02269 -0.00174611 -0.036506" rpy="1.5708 -1.5708 0" />
<geometry>
<mesh filename="package://imported2.stl"/>
</geometry>
<material name="imported2_material">
<color rgba="0.768627 0.886275 0.952941 1.0"/>
</material>
</collision>
<collision>
<origin xyz="-0.0118691 0.07126 -0.0250047" rpy="-3.14159 -1.5708 0" />
<geometry>
<mesh filename="package://imported1.stl"/>
</geometry>
<material name="imported1_material">
<color rgba="0.972549 0.529412 0.00392157 1.0"/>
</material>
</collision>
<visual>
<origin xyz="0 0 0" rpy="0 -0 0" />
<geometry>
<mesh filename="package://assembly_6_1.stl"/>
</geometry>
<material name="assembly_6_1_material">
<color rgba="nan nan nan 1.0"/>
</material>
</visual>
<inertial>
<origin xyz="0 0 0" rpy="0 0 0"/>
<mass value="0" />
<inertia ixx="0" ixy="0"  ixz="0" iyy="0" iyz="0" izz="0" />
</inertial>
</link>

<link name="assembly_1_1">
<collision>
<origin xyz="-0.0417983 -0.04424 0.0695052" rpy="-1.5708 1.49702e-19 2.03954e-20" />
<geometry>
<mesh filename="package://servomotore_hitec_hs485-hb.stl"/>
</geometry>
<material name="servomotore_hitec_hs485-hb_material">
<color rgba="0.792157 0.819608 0.933333 1.0"/>
</material>
</collision>
<collision>
<origin xyz="-0.0417983 -0.04424 0.0695052" rpy="-1.5708 1.49702e-19 2.03954e-20" />
<geometry>
<mesh filename="package://part_3.stl"/>
</geometry>
<material name="part_3_material">
<color rgba="0.792157 0.819608 0.933333 1.0"/>
</material>
</collision>
<collision>
<origin xyz="-3.53884e-16 -0.0465764 -3.60822e-16" rpy="3.14159 3.16747e-17 -3.14159" />
<geometry>
<mesh filename="package://imported1.stl"/>
</geometry>
<material name="imported1_material">
<color rgba="0.917647 0.917647 0.917647 1.0"/>
</material>
</collision>
<collision>
<origin xyz="-3.46945e-16 -0.0480764 -3.747e-16" rpy="-1.5708 -3.15605e-16 1.67908e-15" />
<geometry>
<mesh filename="package://imported36.stl"/>
</geometry>
<material name="imported36_material">
<color rgba="0.917647 0.917647 0.917647 1.0"/>
</material>
</collision>
<collision>
<origin xyz="-0.0417983 -0.04424 0.0695052" rpy="-1.5708 1.49702e-19 2.03954e-20" />
<geometry>
<mesh filename="package://part_5.stl"/>
</geometry>
<material name="part_5_material">
<color rgba="0.792157 0.819608 0.933333 1.0"/>
</material>
</collision>
<collision>
<origin xyz="-0.0417983 -0.04424 0.0695052" rpy="-1.5708 1.49702e-19 2.03954e-20" />
<geometry>
<mesh filename="package://part_4.stl"/>
</geometry>
<material name="part_4_material">
<color rgba="0.792157 0.819608 0.933333 1.0"/>
</material>
</collision>
<collision>
<origin xyz="0 -0.0065 6.93889e-18" rpy="2.67186e-19 1.49702e-19 2.03954e-20" />
<geometry>
<mesh filename="package://ingranaggio_dentato_innesto_servomotore.stl"/>
</geometry>
<material name="ingranaggio_dentato_innesto_servomotore_material">
<color rgba="0.792157 0.819608 0.933333 1.0"/>
</material>
</collision>
<visual>
<origin xyz="0 0 0" rpy="0 -0 0" />
<geometry>
<mesh filename="package://assembly_1_1.stl"/>
</geometry>
<material name="assembly_1_1_material">
<color rgba="nan nan nan 1.0"/>
</material>
</visual>
<inertial>
<origin xyz="0 0 0" rpy="0 0 0"/>
<mass value="0" />
<inertia ixx="0" ixy="0"  ixz="0" iyy="0" iyz="0" izz="0" />
</inertial>
</link>

<joint name="1" type="revolute">
<origin xyz="-0.0118691 0.027953 -0.0250047" rpy="3.14159 0.13886 1.15788e-14" />
<parent link="assembly_6_1" />
<child link="assembly_1_1" />
<axis xyz="0 1 0"/>
<limit effort="1" velocity="20" />
<joint_properties friction="0.0"/>
</joint>

<joint name="2" type="revolute">
<origin xyz="-0.0654471 -0.0818837 0.0798368" rpy="-1.58275 0.00610405 -2.99713" />
<parent link="assembly_3_1" />
<child link="assembly_6_1" />
<axis xyz="0 0 1"/>
<limit effort="1" velocity="20" />
<joint_properties friction="0.0"/>
</joint>

<link name="assembly_4_1">
<collision>
<origin xyz="0.0213487 0.13989 -0.0292906" rpy="-3.14159 3.18262e-16 -1.5708" />
<geometry>
<mesh filename="package://imported11.stl"/>
</geometry>
<material name="imported11_material">
<color rgba="0.231373 0.380392 0.705882 1.0"/>
</material>
</collision>
<collision>
<origin xyz="0.0046269 0.179546 -0.00573332" rpy="1.5708 -1.92601e-15 1.91212" />
<geometry>
<mesh filename="package://imported8.stl"/>
</geometry>
<material name="imported8_material">
<color rgba="0.231373 0.380392 0.705882 1.0"/>
</material>
</collision>
<collision>
<origin xyz="0.0047879 0.180784 -0.0530904" rpy="1.5708 1.5708 0" />
<geometry>
<mesh filename="package://imported30.stl"/>
</geometry>
<material name="imported30_material">
<color rgba="0.231373 0.380392 0.705882 1.0"/>
</material>
</collision>
<collision>
<origin xyz="0 -0.0168782 -0.03075" rpy="7.48023e-19 -5.28497e-18 2.58361e-17" />
<geometry>
<mesh filename="package://imported10.stl"/>
</geometry>
<material name="imported10_material">
<color rgba="0.972549 0.529412 0.00392157 1.0"/>
</material>
</collision>
<collision>
<origin xyz="0.0190627 0.0209676 -0.0584498" rpy="-3.14159 -1.80101e-15 -1.5708" />
<geometry>
<mesh filename="package://asb201b.stl"/>
</geometry>
<material name="asb201b_material">
<color rgba="0.498039 0.498039 0.498039 1.0"/>
</material>
</collision>
<collision>
<origin xyz="0.0060325 0.0240029 -0.0292906" rpy="-1.5708 -1.5708 0" />
<geometry>
<mesh filename="package://at-03.stl"/>
</geometry>
<material name="at-03_material">
<color rgba="0.768627 0.886275 0.952941 1.0"/>
</material>
</collision>
<collision>
<origin xyz="0.0060325 0.0208279 -0.0292906" rpy="-1.86037e-16 -1.5708 0" />
<geometry>
<mesh filename="package://hub-08.stl"/>
</geometry>
<material name="hub-08_material">
<color rgba="0.917647 0.917647 0.917647 1.0"/>
</material>
</collision>
<collision>
<origin xyz="-0.00553287 0.150019 -0.0451801" rpy="1.17843e-15 -1.5708 0" />
<geometry>
<mesh filename="package://imported15.stl"/>
</geometry>
<material name="imported15_material">
<color rgba="0.611765 0.811765 0.921569 1.0"/>
</material>
</collision>
<collision>
<origin xyz="0.0213487 0.0224154 -0.0292906" rpy="-8.66221e-16 1.72784e-15 1.5708" />
<geometry>
<mesh filename="package://imported11.stl"/>
</geometry>
<material name="imported11_material">
<color rgba="0.231373 0.380392 0.705882 1.0"/>
</material>
</collision>
<collision>
<origin xyz="0.0190627 0.170853 -0.0347135" rpy="-3.14159 1.53574e-15 -1.5708" />
<geometry>
<mesh filename="package://asb-04.stl"/>
</geometry>
<material name="asb-04_material">
<color rgba="0.647059 0.647059 0.647059 1.0"/>
</material>
</collision>
<collision>
<origin xyz="0.0060325 0.141478 -0.0292906" rpy="3.14159 -1.5708 0" />
<geometry>
<mesh filename="package://hub-08.stl"/>
</geometry>
<material name="hub-08_material">
<color rgba="0.917647 0.917647 0.917647 1.0"/>
</material>
</collision>
<visual>
<origin xyz="0 0 0" rpy="0 -0 0" />
<geometry>
<mesh filename="package://assembly_4_1.stl"/>
</geometry>
<material name="assembly_4_1_material">
<color rgba="nan nan nan 1.0"/>
</material>
</visual>
<inertial>
<origin xyz="0 0 0" rpy="0 0 0"/>
<mass value="0" />
<inertia ixx="0" ixy="0"  ixz="0" iyy="0" iyz="0" izz="0" />
</inertial>
</link>

<link name="assembly_5_1">
<collision>
<origin xyz="-0.0230885 0.04456 0.0157932" rpy="-1.22947 -4.0021e-16 9.34825e-16" />
<geometry>
<mesh filename="package://servo.stl"/>
</geometry>
<material name="servo_material">
<color rgba="0.25098 0.25098 0.25098 1.0"/>
</material>
</collision>
<collision>
<origin xyz="-0.0230999 0.0464333 0.0164945" rpy="1.91212 -3.66534e-16 8.79191e-16" />
<geometry>
<mesh filename="package://part_1.stl"/>
</geometry>
<material name="part_1_material">
<color rgba="0.501961 0.501961 0.501961 1.0"/>
</material>
</collision>
<collision>
<origin xyz="-0.0380746 -0.0295275 0.01016" rpy="-1.77781e-17 5.97474e-18 -1.48501e-17" />
<geometry>
<mesh filename="package://imported15.stl"/>
</geometry>
<material name="imported15_material">
<color rgba="0.917647 0.917647 0.917647 1.0"/>
</material>
</collision>
<collision>
<origin xyz="-0.0468298 2.77556e-17 -2.498e-16" rpy="-1.22947 -8.01608e-17 6.87249e-16" />
<geometry>
<mesh filename="package://bb-03.stl"/>
</geometry>
<material name="bb-03_material">
<color rgba="0.647059 0.647059 0.647059 1.0"/>
</material>
</collision>
<collision>
<origin xyz="-0.0468298 2.77556e-17 -2.22045e-16" rpy="-1.91212 4.11776e-16 -3.14159" />
<geometry>
<mesh filename="package://imported30.stl"/>
</geometry>
<material name="imported30_material">
<color rgba="0.231373 0.380392 0.705882 1.0"/>
</material>
</collision>
<visual>
<origin xyz="0 0 0" rpy="0 -0 0" />
<geometry>
<mesh filename="package://assembly_5_1.stl"/>
</geometry>
<material name="assembly_5_1_material">
<color rgba="0.25098 0.25098 0.25098 1.0"/>
</material>
</visual>
<inertial>
<origin xyz="-0.0234014 0.0368911 0.013069" rpy="0 0 0"/>
<mass value="0.018017" />
<inertia ixx="1.86281e-06" ixy="-3.23134e-08"  ixz="1.14928e-08" iyy="2.17181e-06" iyz="3.27103e-07" izz="2.97645e-06" />
</inertial>
</link>

<link name="assembly_10_1">
<collision>
<origin xyz="-2.77556e-17 -0.0064008 -0.004327" rpy="2.59109e-17 1.5708 0" />
<geometry>
<mesh filename="package://gripper_wrist.stl"/>
</geometry>
<material name="gripper_wrist_material">
<color rgba="0.768627 0.886275 0.952941 1.0"/>
</material>
</collision>
<collision>
<origin xyz="0.0103124 -7.62e-05 -0.0163031" rpy="3.14159 5.45525e-17 -2.79387e-16" />
<geometry>
<mesh filename="package://servo_body.stl"/>
</geometry>
<material name="servo_body_material">
<color rgba="0.25098 0.25098 0.25098 1.0"/>
</material>
</collision>
<collision>
<origin xyz="0.007495 0 -0.01259" rpy="-1.32243e-17 7.94267e-18 -2.59109e-17" />
<geometry>
<mesh filename="package://horn.stl"/>
</geometry>
<material name="horn_material">
<color rgba="0.917647 0.917647 0.917647 1.0"/>
</material>
</collision>
<visual>
<origin xyz="0 0 0" rpy="0 -0 0" />
<geometry>
<mesh filename="package://assembly_10_1.stl"/>
</geometry>
<material name="assembly_10_1_material">
<color rgba="0.917647 0.917647 0.917647 1.0"/>
</material>
</visual>
<inertial>
<origin xyz="-2.25514e-17 -8.05028e-19 -0.001465" rpy="0 0 0"/>
<mass value="6.42487e-05" />
<inertia ixx="1.82637e-10" ixy="-1.79719e-26"  ixz="1.89881e-27" iyy="1.82637e-10" iyz="-2.68274e-27" izz="2.73347e-10" />
</inertial>
</link>

<link name="assembly_11_1">
<collision>
<origin xyz="0 -1.38778e-17 0" rpy="3.0494e-17 -3.36955e-17 -4.99245e-17" />
<geometry>
<mesh filename="package://servo_output.stl"/>
</geometry>
<material name="servo_output_material">
<color rgba="0.960784 0.960784 0.960784 1.0"/>
</material>
</collision>
<collision>
<origin xyz="0 0.0090678 -2.08167e-17" rpy="1.5708 -1.5708 0" />
<geometry>
<mesh filename="package://gripper_wheel.stl"/>
</geometry>
<material name="gripper_wheel_material">
<color rgba="0.647059 0.647059 0.647059 1.0"/>
</material>
</collision>
<collision>
<origin xyz="-0.00207963 0.0065278 0.0110353" rpy="1.27557e-15 -0.839514 -4.50585e-15" />
<geometry>
<mesh filename="package://gripper_arm.stl"/>
</geometry>
<material name="gripper_arm_material">
<color rgba="0.980392 0.713725 0.00392157 1.0"/>
</material>
</collision>
<collision>
<origin xyz="0.0366356 0.0393579 -0.0258693" rpy="0.878038 -1.85432e-15 1.5708" />
<geometry>
<mesh filename="package://gripper_finger_pad.stl"/>
</geometry>
<material name="gripper_finger_pad_material">
<color rgba="0.615686 0.811765 0.929412 1.0"/>
</material>
</collision>
<collision>
<origin xyz="-0.00398455 0.0013716 -0.0214456" rpy="3.14159 0.878038 -1.49854e-14" />
<geometry>
<mesh filename="package://gripper_finger_left.stl"/>
</geometry>
<material name="gripper_finger_left_material">
<color rgba="0.917647 0.917647 0.917647 1.0"/>
</material>
</collision>
<collision>
<origin xyz="0.00204002 0.0065278 -0.0110785" rpy="-3.14159 0.818534 3.14159" />
<geometry>
<mesh filename="package://gripper_arm.stl"/>
</geometry>
<material name="gripper_arm_material">
<color rgba="0.980392 0.713725 0.00392157 1.0"/>
</material>
</collision>
<collision>
<origin xyz="0.0218998 -0.0125984 3.80425e-05" rpy="7.58991e-16 0.878038 -1.13616e-14" />
<geometry>
<mesh filename="package://gripper_finger_right.stl"/>
</geometry>
<material name="gripper_finger_right_material">
<color rgba="0.498039 0.498039 0.498039 1.0"/>
</material>
</collision>
<collision>
<origin xyz="0.0163216 0.0393579 -0.0427296" rpy="0.878038 5.78516e-16 1.5708" />
<geometry>
<mesh filename="package://gripper_finger_pad.stl"/>
</geometry>
<material name="gripper_finger_pad_material">
<color rgba="0.615686 0.811765 0.929412 1.0"/>
</material>
</collision>
<visual>
<origin xyz="0 0 0" rpy="0 -0 0" />
<geometry>
<mesh filename="package://assembly_11_1.stl"/>
</geometry>
<material name="assembly_11_1_material">
<color rgba="nan nan nan 1.0"/>
</material>
</visual>
<inertial>
<origin xyz="0 0 0" rpy="0 0 0"/>
<mass value="0" />
<inertia ixx="0" ixy="0"  ixz="0" iyy="0" iyz="0" izz="0" />
</inertial>
</link>

<joint name="6" type="revolute">
<origin xyz="2.77556e-17 0.0054864 -0.0163031" rpy="1.67594e-14 0.692758 7.99937e-15" />
<parent link="assembly_10_1" />
<child link="assembly_11_1" />
<axis xyz="0 1 0"/>
<limit effort="1" velocity="20" />
<joint_properties friction="0.0"/>
</joint>

<joint name="5" type="revolute">
<origin xyz="-0.0305835 0.0536627 0.0190268" rpy="2.29434 1.0407 0.651214" />
<parent link="assembly_5_1" />
<child link="assembly_10_1" />
<axis xyz="0 0 1"/>
<limit effort="1" velocity="20" />
<joint_properties friction="0.0"/>
</joint>

<joint name="4" type="revolute">
<origin xyz="0.0046269 0.179546 -0.00723332" rpy="-6.23928e-16 -1.5708 0" />
<parent link="assembly_4_1" />
<child link="assembly_5_1" />
<axis xyz="1 0 0"/>
<limit effort="1" velocity="20" />
<joint_properties friction="0.0"/>
</joint>

<joint name="3" type="revolute">
<origin xyz="0.0719717 -0.062505 0.126071" rpy="1.59791 -1.11408 0.120194" />
<parent link="assembly_3_1" />
<child link="assembly_4_1" />
<axis xyz="0 0 1"/>
<limit effort="1" velocity="20" />
<joint_properties friction="0.0"/>
</joint>


</robot>
